Workbook

Sheet Customer
A1: Selling for large-enterprises | B1: Ex: Vingroup Ecosystem
B3: Business Unit | C3: Ví dụ AI | D3: Số lượng AI systems (ước lượng) | H3: thiết kế mô hình quản lý và điều phối sp AI hiệu quả trong Vingroup
B4: 🚗 VinFast | C4: ADAS, driver monitoring, factory AI, in-car assistant | D4: 20
B5: 🧠 VinAI | C5: Vision, NLP, speech, foundation models | D5: 15
B6: 📊 VinBigData | C6: Chatbot, callbot, voice AI, data platform | D6: 20
B7: 🏥 VinBrain / Vinmec | C7: VinDr, diagnosis AI, clinical support | D7: 12
B8: 🏙️ Smart City / Vinhomes | C8: Camera AI, traffic AI, security | D8: 15
B9: 🤖 Manufacturing / VinMotion | C9: Robot AI, automation, vision QC | D9: 7
B10: 🏨 Vinpearl | C10: Pricing AI, recommendation, ops AI | D10: 7
B11: 🔐 VinCSS | C11: Fraud detection, identity AI | D11: 7
D12: =SUM(D4:D11) -> 103
B13: 2. Tổng hợp toàn hệ sinh thái
B14: Level | C14: Số lượng | D14: Số lượng trung bình
B15: AI products / systems | C15: ~80 – 150 | D15: 110
B16: AI models / pipelines | C16: 100 – 300+ | D16: 150
B17: AI use cases (embedded) | C17: 150 – 300+ | D17: 220
B20: 3. Phân tầng (rất quan trọng cho strategy)
B21: Layer | C21: Mô tả | D21: Số lượng | E21: Trung bình
B22: Core AI Platforms | C22: VinAI, VinBigData | D22: 20–40 | E22: 30
B23: Domain AI Systems | C23: VinFast, Vinmec, Smart City | D23: 40–80 | E23: 60
B24: Embedded AI | C24: camera, chatbot, automation | D24: 50–100+ | E24: 70
B27: 4. Mapping theo mức độ usage (để tính cost/revenue)
B28: Mức độ | C28: % hệ thống | D28: Đặc điểm
B29: Low usage | C29: 0.3 | D29: POC, research
B30: Medium | C30: 0.5 | D30: internal tools
B31: High (production) | C31: 0.2 | D31: always-on AI
C35: Large enterprise | D35: SMEs
B36: TrustLayer AI | C36: 1 khách = 100 AI systems | D36: 10 AI systems
B39: 6. Impact tới business
B40: Metric | C40: Giá trị
B41: API cost | C41: $5 – $50
B42: Pricing potential | C42: $500 – $5,000+
B43: Margin | C43: 90%+
B47: Giả định thực tế (enterprise-ready) | D47: 100 AI systems, chia theo maturity:
B48: Tier | C48: % | D48: Số systems | E48: Hành vi
B49: Low (POC, thử nghiệm) | C49: 0.3 | D49: 30 | E49: ~10 req/tháng
B50: Medium (internal tools) | C50: 0.5 | D50: 50 | E50: ~100 req/tháng
B51: High (production) | C51: 0.2 | D51: 20 | E51: ~1,000 req/tháng
B53: Tổng: ~25,300 requests / tháng
B54: Giả định token / request
...

Sheet 1. Assumptions
B2: Tab 1 — ASSUMPTIONS / Giả định đầu vào
B3: Luật chơi: chỉ điền vào các ô MÀU VÀNG. Các ô khác là công thức và sẽ tự tính.
B5: 1. Product & Pricing / Sản phẩm & Giá
C6: Optimistic | D6: Base | E6: Pessimistic | F6: Đơn vị | G6: Ghi chú / Note
B7: ARPU — Giá bán bình quân/khách/tháng | C7: 800000 | D7: 1700 | E7: 450000 | F7: VND | G7: Pricing cao hơn → khó bán hơn nhưng margin tốt hơn | H7: Willing to pay của khách hàng như thế nào? => Willing to pay của ARPU =? Customers: B2B | I7: GPT-5 mini optimized: $5–15 / khách / tháng Bao nhiêu khách hàng / tháng: 2 khách hàng Tần xuất sử dụng feature: 1 tuần / 1 lần (thường cuối tuần để review & làm report) Mỗi user trong 1 tháng, trung bình họ phát sinh bao nhiêu transaction, để xem họ trả mình bao nhiêu tiền ? Tính bao nhiêu token/ turn ( gồm cả input & output )
B8: Adoption rate — % TAM chuyển thành khách/tháng | C8: 0.012 | D8: 0.006 | E8: 0.002 | F8: %/tháng | G8: % TAM chuyển thành khách trả tiền mới mỗi tháng
B9: Total addressable market (số khách tiềm năng) | C9: 50000 | D9: 2 | E9: 50000 | F9: khách | G9: Tổng số khách hàng tiềm năng có thể tiếp cận được
B11: 2. COGS / Chi phí biến đổi trên mỗi khách hàng
B12: API cost / khách / tháng | C12: 100000 | D12: 75 | E12: 200000 | F12: VND | G12: Tiền gọi OpenAI/Anthropic/Gemini API | H12: 1000 requests/ tháng cho 100 sp AI => Usage × Token × Price
B13: Hidden costs (labeling, retraining, QA) | C13: 30000 | D13: 950 | E13: 100000 | F13: VND | G13: Đừng quên! Đây là cục giết startup AI
B14: Infrastructure (server/cloud) / khách | C14: 20000 | D14: 350 | E14: 50000 | F14: VND | G14: Phần allocate cloud cost cho mỗi khách
B15: → Tổng COGS / khách / tháng | C15: =C12+C13+C14 -> 150000 | D15: =D12+D13+D14 -> 1375 | E15: =E12+E13+E14 -> 350000
B17: 3. Customer Behavior / Hành vi khách hàng
B18: Monthly Churn Rate — % khách rời mỗi tháng | C18: 0.03 | D18: 0.05 | E18: 0.08 | F18: % | G18: Benchmark AI product < 5%/tháng
B19: → Số tháng ở lại trung bình | C19: =IFERROR(1/C18,0) -> 33.333333 | D19: =IFERROR(1/D18,0) -> 20 | E19: =IFERROR(1/E18,0) -> 12.5
B21: 4. Sales & Marketing / Chi phí thu hút khách
B22: CAC — Tổng chi phí có 1 khách hàng mới | C22: 800000 | D22: 500 | E22: 2500000 | F22: VND | G22: Tổng tiền Marketing & Sales / Số khách mới
B24: 5. Fixed Costs / Chi phí cố định hàng tháng
B25: Salaries — Lương team (PM/Dev/Designer) | C25: 80000000 | D25: 100000000 | E25: 120000000 | F25: VND/tháng | G25: Pessimistic = phải hire thêm nếu khó scale
B26: Office, tools, admin | C26: 15000000 | D26: 20000000 | E26: 25000000 | F26: VND/tháng
B27: Marketing budget hàng tháng | C27: 50000000 | D27: 80000000 | E27: 100000000 | F27: VND/tháng
B28: → Tổng Fixed Cost / tháng | C28: =SUM(C25:C27) -> 145000000 | D28: =SUM(D25:D27) -> 200000000 | E28: =SUM(E25:E27) -> 245000000
B30: 6. Initial Investment / Vốn đầu tư ban đầu
B31: Vốn đầu tư ban đầu (build MVP, setup) | C31: 500000000 | D31: 500000000 | E31: 500000000 | F31: VND | G31: Chi phí 1 lần — lương team build MVP, infrastructure setup
B32: Tiền mặt ban đầu (sau khi đã trừ vốn đầu tư) | C32: 3000000000 | D32: 3000000000 | E32: 3000000000 | F32: VND | G32: Số tiền có sẵn để chi trả fixed cost trong giai đoạn đầu
B34: 7. Discount Rate / Tỷ suất chiết khấu (cho NPV)
B35: Annual discount rate (WACC) | C35: 0.2 | D35: 0.2 | E35: 0.2 | F35: %/năm | G35: Mức kỳ vọng tối thiểu của nhà đầu tư cho dự án AI rủi ro
B36: → Monthly discount rate | C36: =(1+C35)^(1/12)-1 -> 0.01530947 | D36: =(1+D35)^(1/12)-1 -> 0.01530947 | E36: =(1+E35)^(1/12)-1 -> 0.01530947
B38: 8. Decision Note / Ghi chú quyết định
B39: Tại sao bạn chọn mức ARPU và CAC như trên? Logic gì để bảo vệ những con số này trước nhà đầu tư? Viết 2-3 câu…
B43: lí do vì sao chọn những chỉ số
B44: thay doi sau tunning

Sheet 2. Unit Economics
B2: Tab 2 — UNIT ECONOMICS / Kinh tế đơn vị
B3: Tự động tính từ Tab 1. Kiểm tra: LTV/CAC > 3 (Base) và CAC Payback < 12 tháng.
B5: Chỉ số | C5: Optimistic | D5: Base | E5: Pessimistic | F5: Đơn vị | G5: Benchmark / Note
B7: Trên mỗi khách hàng / per customer
B8: ARPU / tháng | C8: ='1. Assumptions'!C7 -> 800000 | D8: ='1. Assumptions'!D7 -> 1700 | E8: ='1. Assumptions'!E7 -> 450000 | F8: VND | G8: Liên kết từ Tab Assumptions
B9: COGS / tháng | C9: ='1. Assumptions'!C15 -> 150000 | D9: ='1. Assumptions'!D15 -> 1375 | E9: ='1. Assumptions'!E15 -> 350000 | F9: VND
B10: → Gross Profit / tháng | C10: =C8-C9 -> 650000 | D10: =D8-D9 -> 325 | E10: =E8-E9 -> 100000
B11: → Gross Margin % | C11: =IFERROR(C10/C8,0) -> 0.8125 | D11: =IFERROR(D10/D8,0) -> 0.19117647 | E11: =IFERROR(E10/E8,0) -> 0.22222222 | G11: AI product target: 40-60%. SaaS truyền thống: 80%+
B13: LTV — Customer Lifetime Value
B14: Số tháng ở lại trung bình | C14: ='1. Assumptions'!C19 -> 33.333333 | D14: ='1. Assumptions'!D19 -> 20 | E14: ='1. Assumptions'!E19 -> 12.5 | F14: tháng
B15: → LTV = Gross Profit × Số tháng ở lại | C15: =C10*C14 -> 21666667 | D15: =D10*D14 -> 6500 | E15: =E10*E14 -> 1250000 | G15: Tổng lợi nhuận gộp một khách mang lại trong vòng đời
B17: CAC — Customer Acquisition Cost
B18: CAC — Chi phí thu hút 1 khách | C18: ='1. Assumptions'!C22 -> 800000 | D18: ='1. Assumptions'!D22 -> 500 | E18: ='1. Assumptions'!E22 -> 2500000 | F18: VND
B20: Key Ratios / Tỷ lệ then chốt
B21: → LTV / CAC Ratio | C21: =IFERROR(C15/C18,0) -> 27.083333 | D21: =IFERROR(D15/D18,0) -> 13 | E21: =IFERROR(E15/E18,0) -> 0.5 | G21: 🎯 Target > 3.0x (tiêu chuẩn vàng VC)
B22: → CAC Payback Period | C22: =IFERROR(C18/C10,0) -> 1.2307692 | D22: =IFERROR(D18/D10,0) -> 1.5384615 | E22: =IFERROR(E18/E10,0) -> 25 | G22: 🎯 Target < 12 tháng (early-stage)
B24: Verdict / Kết luận
B25: Unit Economics Status | C25: =IF(AND(C21>=3,C22<=12),"✓ HEALTHY",IF(OR(C21<1,C22>18),"✗ UNHEALTHY","⚠ WATCH")) -> ✓ HEALTHY | D25: =IF(AND(D21>=3,D22<=12),"✓ HEALTHY",IF(OR(D21<1,D22>18),"✗ UNHEALTHY","⚠ WATCH")) -> ✓ HEALTHY | E25: =IF(AND(E21>=3,E22<=12),"✓ HEALTHY",IF(OR(E21<1,E22>18),"✗ UNHEALTHY","⚠ WATCH")) -> ✗ UNHEALTHY

Sheet 3. P&L & ROI
B2: Tab 3 — P&L & ROI / 24 tháng
B4: Chọn scenario: | C4: Base | D4: Đổi scenario tại đây để toàn bộ P&L tự cập nhật
B6: Active scenario index: | C6: =MATCH(C4,{"Optimistic","Base","Pessimistic"},0) -> 2
B7: Selected scenario inputs ↓
B8: ARPU / khách / tháng | C8: =CHOOSE($C$6,'1. Assumptions'!C7,'1. Assumptions'!D7,'1. Assumptions'!E7) -> 1700
B9: Adoption rate | C9: =CHOOSE($C$6,'1. Assumptions'!C8,'1. Assumptions'!D8,'1. Assumptions'!E8) -> 0.006
B10: TAM (số khách tiềm năng) | C10: =CHOOSE($C$6,'1. Assumptions'!C9,'1. Assumptions'!D9,'1. Assumptions'!E9) -> 2
B11: Total COGS / khách | C11: =CHOOSE($C$6,'1. Assumptions'!C15,'1. Assumptions'!D15,'1. Assumptions'!E15) -> 1375
B12: Monthly Churn Rate | C12: =CHOOSE($C$6,'1. Assumptions'!C18,'1. Assumptions'!D18,'1. Assumptions'!E18) -> 0.05
B13: CAC / khách mới | C13: =CHOOSE($C$6,'1. Assumptions'!C22,'1. Assumptions'!D22,'1. Assumptions'!E22) -> 500
B14: Fixed Cost / tháng | C14: =CHOOSE($C$6,'1. Assumptions'!C28,'1. Assumptions'!D28,'1. Assumptions'!E28) -> 200000000
B15: Initial Investment | C15: =CHOOSE($C$6,'1. Assumptions'!C31,'1. Assumptions'!D31,'1. Assumptions'!E31) -> 500000000
B16: Initial Cash | C16: =CHOOSE($C$6,'1. Assumptions'!C32,'1. Assumptions'!D32,'1. Assumptions'!E32) -> 3000000000
B17: Monthly Discount Rate | C17: =CHOOSE($C$6,'1. Assumptions'!C36,'1. Assumptions'!D36,'1. Assumptions'!E36) -> 0.01530947
B20: P&L Projection — 24 months (VND)
B21: Month | C21: M1 | D21: M2 | E21: M3 | F21: M4 | G21: M5 | H21: M6 | I21: M7 | J21: M8 | K21: M9 | L21: M10 | M21: M11 | N21: M12 | O21: M13 | P21: M14 | Q21: M15 | R21: M16 | S21: M17 | T21: M18 | U21: M19 | V21: M20 | W21: M21 | X21: M22 | Y21: M23 | Z21: M24 | AA21: TOTAL
B22: New customers acquired | C22: =ROUND($C$10*$C$9,0) -> 0 | D22: =ROUND($C$10*$C$9,0) -> 0 | E22: =ROUND($C$10*$C$9,0) -> 0 | F22: =ROUND($C$10*$C$9,0) -> 0 | G22: =ROUND($C$10*$C$9,0) -> 0 | H22: =ROUND($C$10*$C$9,0) -> 0 | I22: =ROUND($C$10*$C$9,0) -> 0 | J22: =ROUND($C$10*$C$9,0) -> 0 | ... Z22: =ROUND($C$10*$C$9,0) -> 0 | AA22: =SUM(C22:Z22) -> 0
B23: Active customers (end of month) | C23: =C22 -> 0 | D23: =C23*(1-$C$12)+D22 -> 0 | E23: =D23*(1-$C$12)+E22 -> 0 | F23: =E23*(1-$C$12)+F22 -> 0 | G23: =F23*(1-$C$12)+G22 -> 0 | H23: =G23*(1-$C$12)+H22 -> 0 | I23: =H23*(1-$C$12)+I22 -> 0 | J23: =I23*(1-$C$12)+J22 -> 0 | K23: =J23*(1-$C$12)+K22 -> 0 | ... Z23: =Y23*(1-$C$12)+Z22 -> 0
B25: Revenue | C25: =C23*$C$8 -> 0 | D25: =D23*$C$8 -> 0 | E25: =E23*$C$8 -> 0 | F25: =F23*$C$8 -> 0 | G25: =G23*$C$8 -> 0 | H25: =H23*$C$8 -> 0 | I25: =I23*$C$8 -> 0 | J25: =J23*$C$8 -> 0 | ... Z25: =Z23*$C$8 -> 0 | AA25: =SUM(C25:Z25) -> 0
B26: COGS (variable cost) | C26: =C23*$C$11 -> 0 | D26: =D23*$C$11 -> 0 | E26: =E23*$C$11 -> 0 | F26: =F23*$C$11 -> 0 | G26: =G23*$C$11 -> 0 | H26: =H23*$C$11 -> 0 | I26: =I23*$C$11 -> 0 | J26: =J23*$C$11 -> 0 | ... Z26: =Z23*$C$11 -> 0 | AA26: =SUM(C26:Z26) -> 0
B27: Gross Profit | C27: =C25-C26 -> 0 | D27: =D25-D26 -> 0 | E27: =E25-E26 -> 0 | F27: =F25-F26 -> 0 | G27: =G25-G26 -> 0 | H27: =H25-H26 -> 0 | I27: =I25-I26 -> 0 | J27: =J25-J26 -> 0 | ... Z27: =Z25-Z26 -> 0 | AA27: =SUM(C27:Z27) -> 0
B28: Marketing/Acquisition cost | C28: =C22*$C$13 -> 0 | D28: =D22*$C$13 -> 0 | E28: =E22*$C$13 -> 0 | F28: =F22*$C$13 -> 0 | G28: =G22*$C$13 -> 0 | H28: =H22*$C$13 -> 0 | I28: =I22*$C$13 -> 0 | J28: =J22*$C$13 -> 0 | ... Z28: =Z22*$C$13 -> 0 | AA28: =SUM(C28:Z28) -> 0
B29: Fixed cost (salaries + ops) | C29: =$C$14 -> 200000000 | D29: =$C$14 -> 200000000 | E29: =$C$14 -> 200000000 | F29: =$C$14 -> 200000000 | G29: =$C$14 -> 200000000 | H29: =$C$14 -> 200000000 | I29: =$C$14 -> 200000000 | J29: =$C$14 -> 200000000 | ... Z29: =$C$14 -> 200000000 | AA29: =SUM(C29:Z29) -> 4800000000
B30: Operating Profit (EBITDA) | C30: =C27-C28-C29 -> -200000000 | D30: =D27-D28-D29 -> -200000000 | E30: =E27-E28-E29 -> -200000000 | F30: =F27-F28-F29 -> -200000000 | G30: =G27-G28-G29 -> -200000000 | H30: =H27-H28-H29 -> -200000000 | I30: =I27-I28-I29 -> -200000000 | J30: =J27-J28-J29 -> -200000000 | ... Z30: =Z27-Z28-Z29 -> -200000000 | AA30: =SUM(C30:Z30) -> -4800000000
B32: Cash Flow (after investment) | C32: =C30-$C$15 -> -700000000 | D32: =D30 -> -200000000 | E32: =E30 -> -200000000 | F32: =F30 -> -200000000 | G32: =G30 -> -200000000 | H32: =H30 -> -200000000 | I32: =I30 -> -200000000 | J32: =J30 -> -200000000 | K32: =K30 -> -200000000 | ... Z32: =Z30 -> -200000000 | AA32: =SUM(C32:Z32) -> -5300000000
B33: Cash Position (cumulative) | C33: =$C$16+C32 -> 2300000000 | D33: =C33+D32 -> 2100000000 | E33: =D33+E32 -> 1900000000 | F33: =E33+F32 -> 1700000000 | G33: =F33+G32 -> 1500000000 | H33: =G33+H32 -> 1300000000 | I33: =H33+I32 -> 1100000000 | J33: =I33+J32 -> 900000000 | K33: =J33+K32 -> 700000000 | ... Z33: =Y33+Z32 -> -2300000000
B36: ROI Metrics / Chỉ số đánh giá tổng thể dự án
B37: NPV (Net Present Value, mil VND) | C37: =(NPV($C$17,D32:Z32)+C32)/1000000 -> -4552.8306 | D37: ="(target: > 0)" -> (target: > 0)
B38: IRR (Annual) | C38: =IFERROR((1+IRR(C32:Z32))^12-1,0) -> 0 | D38: ="(target: > "&TEXT(CHOOSE($C$6,'1. Assumptions'!C35,'1. Assumptions'!D35,'1. Assumptions'!E35),"0.0%")&")" -> (target: > 20.0%)
B39: Project Payback (months) | C39: =IFERROR(MATCH(TRUE(),INDEX(C41:Z41>=0,0),0),"> 24") -> > 24 | D39: ="(target: < 24)" -> (target: < 24)
B40: Runway (months until cash = 0) | C40: =IFERROR(MATCH(TRUE(),INDEX(C33:Z33<0,0),0)-1,">= 24") -> 12 | D40: ="(target: >= 12)" -> (target: >= 12)
B41: (helper: cumulative cash flow) | C41: =C32 -> -700000000 | D41: =C41+D32 -> -900000000 | E41: =D41+E32 -> -1100000000 | F41: =E41+F32 -> -1300000000 | G41: =F41+G32 -> -1500000000 | H41: =G41+H32 -> -1700000000 | I41: =H41+I32 -> -1900000000 | J41: =I41+J32 -> -2100000000 | K41: =J41+K32 -> -2300000000 | ... Z41: =Y41+Z32 -> -5300000000
B43: Final Verdict / Có nên làm dự án này?
B44: Project Decision | C44: =IF(AND(C37>0,C38>CHOOSE($C$6,'1. Assumptions'!C35,'1. Assumptions'!D35,'1. Assumptions'!E35)),"✓ GO — NPV+ và IRR > WACC",IF(C37<0,"✗ NO-GO — NPV âm: dự án không tạo giá trị","⚠ HOLD — IRR thấp hơn kỳ vọng, cần điều chỉnh")) -> ✗ NO-GO — NPV âm: dự án không tạo giá trị
